Workbook

Sheet 📝 Weekly Tracker
B2: 📝 Weekly Tracker — plan your 168 hours
B3: Only edit the LIGHT-BLUE cells. Every other number updates automatically — here, on the Dashboard and in every tracker.
B5: 😴 SLEEP
B6: I sleep for around | C6: 8 | D6: hours per night. | E6: This means I spend | F6: =C6*7 -> 56 | G6: hours per week sleeping.
B7: I wind down for | C7: 10 | D7: minutes before sleeping. | E7: This means I spend | F7: =C7*7/60 -> 1.1666667 | G7: hours per week preparing to sleep.
B8: My wake-up routine takes | C8: 0 | D8: minutes each morning. | E8: This means I spend | F8: =C8*7/60 -> 0 | G8: hours per week waking up.
E9: 😴 In total, I spend | F9: =F6+F7+F8 -> 57.166667 | G9: hours per week on sleep-related things.
E10: ✅ That leaves me with | F10: =168-F9 -> 110.83333 | G10: hours per week for everything else.
B12: 💻 WORK
B13: I work for around | C13: 8 | D13: hours per day (excluding lunch break).
B14: I work | C14: 6 | D14: days per week. | E14: This means I spend | F14: =C13*C14 -> 48 | G14: hours per week officially working.
B15: My lunch break is | C15: 30 | D15: minutes per working day. | E15: This means I spend | F15: =C15*C14/60 -> 3 | G15: hours per week on my lunch break.
B16: My commute is | C16: 0 | D16: minutes each way. | E16: This means I spend | F16: =C16*2*C14/60 -> 0 | G16: hours per week commuting.
B17: I spend | C17: 10 | D17: minutes per day getting ready for work. | E17: This means I spend | F17: =C17*C14/60 -> 1 | G17: hours per week getting ready for work.
B18: I spend | C18: 10 | D18: minutes per day getting changed after work. | E18: This means I spend | F18: =C18*C14/60 -> 1 | G18: hours per week getting changed after work.
B19: … of which meetings take | C19: 5 | D19: hours per week. | G19: already inside your working hours — not added again
B20: … and deep work takes | C20: 12 | D20: hours per week. | G20: already inside your working hours — not added again
E21: 💻 In total, I spend | F21: =F14+F15+F16+F17+F18 -> 53 | G21: hours per week working.
E22: ✅ That leaves me with | F22: =F10-F21 -> 57.833333 | G22: hours per week for everything else.
B24: 🍕 FOOD
B25: Each day, I spend around | C25: 15 | D25: minutes eating breakfast.
B26: And another | C26: 0 | D26: minutes preparing/cooking/ordering it.
E27: Which means I spend | F27: =(C25+C26)*7/60 -> 1.75 | G27: hours per week on breakfast.
B28: Each non-work day, I spend | C28: 40 | D28: minutes eating lunch.
B29: And another | C29: 0 | D29: minutes preparing/cooking/ordering it.
E30: Which means I spend | F30: =(C28+C29)*(7-C14)/60 -> 0.66666667 | G30: hours per week on lunch (excluding work days).
B31: Each day, I spend around | C31: 30 | D31: minutes eating dinner.
B32: And another | C32: 0 | D32: minutes preparing/cooking/ordering it.
E33: Which means I spend | F33: =(C31+C32)*7/60 -> 3.5 | G33: hours per week on dinner.
E34: 🍕 In total, I spend | F34: =F27+F30+F33 -> 5.9166667 | G34: hours per week on cooking +/- eating food.
E35: ✅ That leaves me with | F35: =F22-F34 -> 51.916667 | G35: hours per week for everything else.
B37: 🧹 HOUSEHOLD CHORES
B38: I do the groceries | C38: 2 | D38: times per week.
B39: Each grocery session takes | C39: 120 | D39: minutes (including travel, loading, unloading etc). | E39: This means I spend | F39: =C38*C39/60 -> 4 | G39: hours per week on groceries.
B40: I clean the house approx. | C40: 1 | D40: times per week.
B41: Each cleaning session takes | C41: 60 | D41: minutes. | E41: This means I spend | F41: =C40*C41/60 -> 1 | G41: hours per week on cleaning.
B42: I do laundry | C42: 0 | D42: times per week.
B43: Each laundry session takes me | C43: 0 | D43: minutes. | E43: This means I spend | F43: =C42*C43/60 -> 0 | G43: hours per week on laundry.
B44: I do other misc. chores | C44: 1 | D44: hour(s) per week. | E44: This means I spend | F44: =C44 -> 1 | G44: hours per week on misc. chores.
E45: 🧹 In total, I spend | F45: =F39+F41+F43+F44 -> 6 | G45: hours per week on chores.
...

Sheet ⚙️ Settings
B2: ⚙️ Settings — master data
B3: One source of truth. Add your own categories in the light-blue rows — every tracker and the Dashboard pick them up automatically.
B5: ⏱️ CONSTANTS
B6: Hours per day | D6: 24
B7: Hours per week | D7: =D6*7 -> 168
B8: Weeks per month | D8: 4
B9: Weeks per year | D9: 52
B12: 🗂️ MASTER CATEGORY TABLE
C13: Category | D13: Hours / wk | E13: % of week | F13: Per day | G13: Productive | H13: Min h/wk | I13: Max h/wk | J13: Status
B14: 😴 | C14: Sleep | D14: ='📝 Weekly Tracker'!F9 -> 57.166667 | E14: =IF($C14="","",$D14/'⚙️ Settings'!$D$7) -> 0.34027778 | F14: =IF($C14="","",$D14/7) -> 8.1666667 | G14: =FALSE() -> FALSE | H14: 49 | I14: 63 | J14: =IF($C14="","",IF(AND($H14<>"",$D14<$H14),"🔻 Low",IF(AND($I14<>"",$D14>$I14),"🔺 High","✅ OK"))) -> ✅ OK
B15: 💻 | C15: Work | D15: ='📝 Weekly Tracker'!F21 -> 53 | E15: =IF($C15="","",$D15/'⚙️ Settings'!$D$7) -> 0.31547619 | F15: =IF($C15="","",$D15/7) -> 7.5714286 | G15: =TRUE() -> TRUE | I15: 55 | J15: =IF($C15="","",IF(AND($H15<>"",$D15<$H15),"🔻 Low",IF(AND($I15<>"",$D15>$I15),"🔺 High","✅ OK"))) -> ✅ OK
B16: 🍕 | C16: Food | D16: ='📝 Weekly Tracker'!F34 -> 5.9166667 | E16: =IF($C16="","",$D16/'⚙️ Settings'!$D$7) -> 0.035218254 | F16: =IF($C16="","",$D16/7) -> 0.8452381 | G16: =FALSE() -> FALSE | H16: 3.5 | I16: 21 | J16: =IF($C16="","",IF(AND($H16<>"",$D16<$H16),"🔻 Low",IF(AND($I16<>"",$D16>$I16),"🔺 High","✅ OK"))) -> ✅ OK
B17: 🧹 | C17: Household Chores | D17: ='📝 Weekly Tracker'!F45 -> 6 | E17: =IF($C17="","",$D17/'⚙️ Settings'!$D$7) -> 0.035714286 | F17: =IF($C17="","",$D17/7) -> 0.85714286 | G17: =FALSE() -> FALSE | I17: 15 | J17: =IF($C17="","",IF(AND($H17<>"",$D17<$H17),"🔻 Low",IF(AND($I17<>"",$D17>$I17),"🔺 High","✅ OK"))) -> ✅ OK
B18: 👶 | C18: Childcare | D18: ='📝 Weekly Tracker'!F53 -> 16 | E18: =IF($C18="","",$D18/'⚙️ Settings'!$D$7) -> 0.095238095 | F18: =IF($C18="","",$D18/7) -> 2.2857143 | G18: =FALSE() -> FALSE | J18: =IF($C18="","",IF(AND($H18<>"",$D18<$H18),"🔻 Low",IF(AND($I18<>"",$D18>$I18),"🔺 High","✅ OK"))) -> ✅ OK
B19: 🏋️ | C19: Fitness | D19: ='📝 Weekly Tracker'!F59 -> 10 | E19: =IF($C19="","",$D19/'⚙️ Settings'!$D$7) -> 0.05952381 | F19: =IF($C19="","",$D19/7) -> 1.4285714 | G19: =TRUE() -> TRUE | H19: 3 | I19: 20 | J19: =IF($C19="","",IF(AND($H19<>"",$D19<$H19),"🔻 Low",IF(AND($I19<>"",$D19>$I19),"🔺 High","✅ OK"))) -> ✅ OK
B20: 📺 | C20: Entertainment | D20: ='📝 Weekly Tracker'!F68 -> 12 | E20: =IF($C20="","",$D20/'⚙️ Settings'!$D$7) -> 0.071428571 | F20: =IF($C20="","",$D20/7) -> 1.7142857 | G20: =FALSE() -> FALSE | I20: 25 | J20: =IF($C20="","",IF(AND($H20<>"",$D20<$H20),"🔻 Low",IF(AND($I20<>"",$D20>$I20),"🔺 High","✅ OK"))) -> ✅ OK
B21: 👨‍👩‍👧 | C21: Relationships | D21: ='📝 Weekly Tracker'!F74 -> 6 | E21: =IF($C21="","",$D21/'⚙️ Settings'!$D$7) -> 0.035714286 | F21: =IF($C21="","",$D21/7) -> 0.85714286 | G21: =FALSE() -> FALSE | H21: 3 | J21: =IF($C21="","",IF(AND($H21<>"",$D21<$H21),"🔻 Low",IF(AND($I21<>"",$D21>$I21),"🔺 High","✅ OK"))) -> ✅ OK
B22: 📚 | C22: Learning | D22: ='📝 Weekly Tracker'!F81 -> 0 | E22: =IF($C22="","",$D22/'⚙️ Settings'!$D$7) -> 0 | F22: =IF($C22="","",$D22/7) -> 0 | G22: =TRUE() -> TRUE | H22: 1 | J22: =IF($C22="","",IF(AND($H22<>"",$D22<$H22),"🔻 Low",IF(AND($I22<>"",$D22>$I22),"🔺 High","✅ OK"))) -> 🔻 Low
B23: 🌱 | C23: Personal Development | D23: ='📝 Weekly Tracker'!F88 -> 0 | E23: =IF($C23="","",$D23/'⚙️ Settings'!$D$7) -> 0 | F23: =IF($C23="","",$D23/7) -> 0 | G23: =TRUE() -> TRUE | H23: 1 | J23: =IF($C23="","",IF(AND($H23<>"",$D23<$H23),"🔻 Low",IF(AND($I23<>"",$D23>$I23),"🔺 High","✅ OK"))) -> 🔻 Low
B24: 🙏 | C24: Spiritual | D24: ='📝 Weekly Tracker'!F94 -> 0 | E24: =IF($C24="","",$D24/'⚙️ Settings'!$D$7) -> 0 | F24: =IF($C24="","",$D24/7) -> 0 | G24: =FALSE() -> FALSE | J24: =IF($C24="","",IF(AND($H24<>"",$D24<$H24),"🔻 Low",IF(AND($I24<>"",$D24>$I24),"🔺 High","✅ OK"))) -> ✅ OK
B25: 🚗 | C25: Travel | D25: ='📝 Weekly Tracker'!F100 -> 0 | E25: =IF($C25="","",$D25/'⚙️ Settings'!$D$7) -> 0 | F25: =IF($C25="","",$D25/7) -> 0 | G25: =FALSE() -> FALSE | J25: =IF($C25="","",IF(AND($H25<>"",$D25<$H25),"🔻 Low",IF(AND($I25<>"",$D25>$I25),"🔺 High","✅ OK"))) -> ✅ OK
B26: 🗂️ | C26: Admin | D26: ='📝 Weekly Tracker'!F106 -> 0 | E26: =IF($C26="","",$D26/'⚙️ Settings'!$D$7) -> 0 | F26: =IF($C26="","",$D26/7) -> 0 | G26: =TRUE() -> TRUE | J26: =IF($C26="","",IF(AND($H26<>"",$D26<$H26),"🔻 Low",IF(AND($I26<>"",$D26>$I26),"🔺 High","✅ OK"))) -> ✅ OK
E27: =IF($C27="","",$D27/'⚙️ Settings'!$D$7) | F27: =IF($C27="","",$D27/7) | G27: =FALSE() -> FALSE | J27: =IF($C27="","",IF(AND($H27<>"",$D27<$H27),"🔻 Low",IF(AND($I27<>"",$D27>$I27),"🔺 High","✅ OK")))
E28: =IF($C28="","",$D28/'⚙️ Settings'!$D$7) | F28: =IF($C28="","",$D28/7) | G28: =FALSE() -> FALSE | J28: =IF($C28="","",IF(AND($H28<>"",$D28<$H28),"🔻 Low",IF(AND($I28<>"",$D28>$I28),"🔺 High","✅ OK")))
E29: =IF($C29="","",$D29/'⚙️ Settings'!$D$7) | F29: =IF($C29="","",$D29/7) | G29: =FALSE() -> FALSE | J29: =IF($C29="","",IF(AND($H29<>"",$D29<$H29),"🔻 Low",IF(AND($I29<>"",$D29>$I29),"🔺 High","✅ OK")))
E30: =IF($C30="","",$D30/'⚙️ Settings'!$D$7) | F30: =IF($C30="","",$D30/7) | G30: =FALSE() -> FALSE | J30: =IF($C30="","",IF(AND($H30<>"",$D30<$H30),"🔻 Low",IF(AND($I30<>"",$D30>$I30),"🔺 High","✅ OK")))
E31: =IF($C31="","",$D31/'⚙️ Settings'!$D$7) | F31: =IF($C31="","",$D31/7) | G31: =FALSE() -> FALSE | J31: =IF($C31="","",IF(AND($H31<>"",$D31<$H31),"🔻 Low",IF(AND($I31<>"",$D31>$I31),"🔺 High","✅ OK")))
C33: Total allocated | D33: =SUM(D14:D31) -> 166.08333
C34: Free time (168 − allocated) | D34: ='⚙️ Settings'!$D$7-D33 -> 1.9166667
C35: Productive hours | D35: =SUMPRODUCT(--(G14:G31=TRUE()),D14:D31) -> 63

Sheet 📅 Daily Tracker
B2: 📅 Daily Tracker — log what actually happened
B3: Type real hours in the light-blue grid. Categories flow in from ⚙️ Settings automatically.
B5: Category | C5: Plan/day | D5: Mon | E5: Tue | F5: Wed | G5: Thu | H5: Fri | I5: Sat | J5: Sun | K5: Week | L5: vs plan
B6: =IF('⚙️ Settings'!C14="","",'⚙️ Settings'!B14&" "&'⚙️ Settings'!C14) -> 😴 Sleep | C6: =IF($B6="","",'⚙️ Settings'!D14/7) -> 8.1666667 | K6: =IF($B6="","",SUM(D6:J6)) -> 0 | L6: =IF($B6="","",K6-'⚙️ Settings'!D14) -> -57.166667
B7: =IF('⚙️ Settings'!C15="","",'⚙️ Settings'!B15&" "&'⚙️ Settings'!C15) -> 💻 Work | C7: =IF($B7="","",'⚙️ Settings'!D15/7) -> 7.5714286 | K7: =IF($B7="","",SUM(D7:J7)) -> 0 | L7: =IF($B7="","",K7-'⚙️ Settings'!D15) -> -53
B8: =IF('⚙️ Settings'!C16="","",'⚙️ Settings'!B16&" "&'⚙️ Settings'!C16) -> 🍕 Food | C8: =IF($B8="","",'⚙️ Settings'!D16/7) -> 0.8452381 | K8: =IF($B8="","",SUM(D8:J8)) -> 0 | L8: =IF($B8="","",K8-'⚙️ Settings'!D16) -> -5.9166667
B9: =IF('⚙️ Settings'!C17="","",'⚙️ Settings'!B17&" "&'⚙️ Settings'!C17) -> 🧹 Household Chores | C9: =IF($B9="","",'⚙️ Settings'!D17/7) -> 0.85714286 | K9: =IF($B9="","",SUM(D9:J9)) -> 0 | L9: =IF($B9="","",K9-'⚙️ Settings'!D17) -> -6
B10: =IF('⚙️ Settings'!C18="","",'⚙️ Settings'!B18&" "&'⚙️ Settings'!C18) -> 👶 Childcare | C10: =IF($B10="","",'⚙️ Settings'!D18/7) -> 2.2857143 | K10: =IF($B10="","",SUM(D10:J10)) -> 0 | L10: =IF($B10="","",K10-'⚙️ Settings'!D18) -> -16
B11: =IF('⚙️ Settings'!C19="","",'⚙️ Settings'!B19&" "&'⚙️ Settings'!C19) -> 🏋️ Fitness | C11: =IF($B11="","",'⚙️ Settings'!D19/7) -> 1.4285714 | K11: =IF($B11="","",SUM(D11:J11)) -> 0 | L11: =IF($B11="","",K11-'⚙️ Settings'!D19) -> -10
B12: =IF('⚙️ Settings'!C20="","",'⚙️ Settings'!B20&" "&'⚙️ Settings'!C20) -> 📺 Entertainment | C12: =IF($B12="","",'⚙️ Settings'!D20/7) -> 1.7142857 | K12: =IF($B12="","",SUM(D12:J12)) -> 0 | L12: =IF($B12="","",K12-'⚙️ Settings'!D20) -> -12
B13: =IF('⚙️ Settings'!C21="","",'⚙️ Settings'!B21&" "&'⚙️ Settings'!C21) -> 👨‍👩‍👧 Relationships | C13: =IF($B13="","",'⚙️ Settings'!D21/7) -> 0.85714286 | K13: =IF($B13="","",SUM(D13:J13)) -> 0 | L13: =IF($B13="","",K13-'⚙️ Settings'!D21) -> -6
B14: =IF('⚙️ Settings'!C22="","",'⚙️ Settings'!B22&" "&'⚙️ Settings'!C22) -> 📚 Learning | C14: =IF($B14="","",'⚙️ Settings'!D22/7) -> 0 | K14: =IF($B14="","",SUM(D14:J14)) -> 0 | L14: =IF($B14="","",K14-'⚙️ Settings'!D22) -> 0
B15: =IF('⚙️ Settings'!C23="","",'⚙️ Settings'!B23&" "&'⚙️ Settings'!C23) -> 🌱 Personal Development | C15: =IF($B15="","",'⚙️ Settings'!D23/7) -> 0 | K15: =IF($B15="","",SUM(D15:J15)) -> 0 | L15: =IF($B15="","",K15-'⚙️ Settings'!D23) -> 0
B16: =IF('⚙️ Settings'!C24="","",'⚙️ Settings'!B24&" "&'⚙️ Settings'!C24) -> 🙏 Spiritual | C16: =IF($B16="","",'⚙️ Settings'!D24/7) -> 0 | K16: =IF($B16="","",SUM(D16:J16)) -> 0 | L16: =IF($B16="","",K16-'⚙️ Settings'!D24) -> 0
B17: =IF('⚙️ Settings'!C25="","",'⚙️ Settings'!B25&" "&'⚙️ Settings'!C25) -> 🚗 Travel | C17: =IF($B17="","",'⚙️ Settings'!D25/7) -> 0 | K17: =IF($B17="","",SUM(D17:J17)) -> 0 | L17: =IF($B17="","",K17-'⚙️ Settings'!D25) -> 0
... B23: =IF('⚙️ Settings'!C31="","",'⚙️ Settings'!B31&" "&'⚙️ Settings'!C31) | C23: =IF($B23="","",'⚙️ Settings'!D31/7) | K23: =IF($B23="","",SUM(D23:J23)) | L23: =IF($B23="","",K23-'⚙️ Settings'!D31)
B24: Hours logged | D24: =SUM(D6:D23) -> 0 | E24: =SUM(E6:E23) -> 0 | F24: =SUM(F6:F23) -> 0 | G24: =SUM(G6:G23) -> 0 | H24: =SUM(H6:H23) -> 0 | I24: =SUM(I6:I23) -> 0 | J24: =SUM(J6:J23) -> 0 | K24: =SUM(K6:K23) -> 0
B25: Unlogged (24 − logged) | D25: =24-D24 -> 24 | E25: =24-E24 -> 24 | F25: =24-F24 -> 24 | G25: =24-G24 -> 24 | H25: =24-H24 -> 24 | I25: =24-I24 -> 24 | J25: =24-J24 -> 24 | K25: ='⚙️ Settings'!$D$7-K24 -> 168

Sheet 📈 Weekly Review
B2: 📈 Weekly Review — planned vs actual
B3: Planned comes from 📝 Weekly Tracker; actual from 📅 Daily Tracker. Nothing to type here.
B5: Category | C5: Planned | D5: Actual | E5: Diff | F5: % of plan | G5: % of week
B6: =IF('⚙️ Settings'!C14="","",'⚙️ Settings'!B14&" "&'⚙️ Settings'!C14) -> 😴 Sleep | C6: =IF($B6="","",'⚙️ Settings'!D14) -> 57.166667 | D6: =IF($B6="","",'📅 Daily Tracker'!K6) -> 0 | E6: =IF($B6="","",D6-C6) -> -57.166667 | F6: =IF(OR($B6="",C6=0),"",D6/C6) -> 0 | G6: =IF($B6="","",C6/'⚙️ Settings'!$D$7) -> 0.34027778
B7: =IF('⚙️ Settings'!C15="","",'⚙️ Settings'!B15&" "&'⚙️ Settings'!C15) -> 💻 Work | C7: =IF($B7="","",'⚙️ Settings'!D15) -> 53 | D7: =IF($B7="","",'📅 Daily Tracker'!K7) -> 0 | E7: =IF($B7="","",D7-C7) -> -53 | F7: =IF(OR($B7="",C7=0),"",D7/C7) -> 0 | G7: =IF($B7="","",C7/'⚙️ Settings'!$D$7) -> 0.31547619
B8: =IF('⚙️ Settings'!C16="","",'⚙️ Settings'!B16&" "&'⚙️ Settings'!C16) -> 🍕 Food | C8: =IF($B8="","",'⚙️ Settings'!D16) -> 5.9166667 | D8: =IF($B8="","",'📅 Daily Tracker'!K8) -> 0 | E8: =IF($B8="","",D8-C8) -> -5.9166667 | F8: =IF(OR($B8="",C8=0),"",D8/C8) -> 0 | G8: =IF($B8="","",C8/'⚙️ Settings'!$D$7) -> 0.035218254
B9: =IF('⚙️ Settings'!C17="","",'⚙️ Settings'!B17&" "&'⚙️ Settings'!C17) -> 🧹 Household Chores | C9: =IF($B9="","",'⚙️ Settings'!D17) -> 6 | D9: =IF($B9="","",'📅 Daily Tracker'!K9) -> 0 | E9: =IF($B9="","",D9-C9) -> -6 | F9: =IF(OR($B9="",C9=0),"",D9/C9) -> 0 | G9: =IF($B9="","",C9/'⚙️ Settings'!$D$7) -> 0.035714286
B10: =IF('⚙️ Settings'!C18="","",'⚙️ Settings'!B18&" "&'⚙️ Settings'!C18) -> 👶 Childcare | C10: =IF($B10="","",'⚙️ Settings'!D18) -> 16 | D10: =IF($B10="","",'📅 Daily Tracker'!K10) -> 0 | E10: =IF($B10="","",D10-C10) -> -16 | F10: =IF(OR($B10="",C10=0),"",D10/C10) -> 0 | G10: =IF($B10="","",C10/'⚙️ Settings'!$D$7) -> 0.095238095
B11: =IF('⚙️ Settings'!C19="","",'⚙️ Settings'!B19&" "&'⚙️ Settings'!C19) -> 🏋️ Fitness | C11: =IF($B11="","",'⚙️ Settings'!D19) -> 10 | D11: =IF($B11="","",'📅 Daily Tracker'!K11) -> 0 | E11: =IF($B11="","",D11-C11) -> -10 | F11: =IF(OR($B11="",C11=0),"",D11/C11) -> 0 | G11: =IF($B11="","",C11/'⚙️ Settings'!$D$7) -> 0.05952381
B12: =IF('⚙️ Settings'!C20="","",'⚙️ Settings'!B20&" "&'⚙️ Settings'!C20) -> 📺 Entertainment | C12: =IF($B12="","",'⚙️ Settings'!D20) -> 12 | D12: =IF($B12="","",'📅 Daily Tracker'!K12) -> 0 | E12: =IF($B12="","",D12-C12) -> -12 | F12: =IF(OR($B12="",C12=0),"",D12/C12) -> 0 | G12: =IF($B12="","",C12/'⚙️ Settings'!$D$7) -> 0.071428571
B13: =IF('⚙️ Settings'!C21="","",'⚙️ Settings'!B21&" "&'⚙️ Settings'!C21) -> 👨‍👩‍👧 Relationships | C13: =IF($B13="","",'⚙️ Settings'!D21) -> 6 | D13: =IF($B13="","",'📅 Daily Tracker'!K13) -> 0 | E13: =IF($B13="","",D13-C13) -> -6 | F13: =IF(OR($B13="",C13=0),"",D13/C13) -> 0 | G13: =IF($B13="","",C13/'⚙️ Settings'!$D$7) -> 0.035714286
B14: =IF('⚙️ Settings'!C22="","",'⚙️ Settings'!B22&" "&'⚙️ Settings'!C22) -> 📚 Learning | C14: =IF($B14="","",'⚙️ Settings'!D22) -> 0 | D14: =IF($B14="","",'📅 Daily Tracker'!K14) -> 0 | E14: =IF($B14="","",D14-C14) -> 0 | F14: =IF(OR($B14="",C14=0),"",D14/C14) | G14: =IF($B14="","",C14/'⚙️ Settings'!$D$7) -> 0
B15: =IF('⚙️ Settings'!C23="","",'⚙️ Settings'!B23&" "&'⚙️ Settings'!C23) -> 🌱 Personal Development | C15: =IF($B15="","",'⚙️ Settings'!D23) -> 0 | D15: =IF($B15="","",'📅 Daily Tracker'!K15) -> 0 | E15: =IF($B15="","",D15-C15) -> 0 | F15: =IF(OR($B15="",C15=0),"",D15/C15) | G15: =IF($B15="","",C15/'⚙️ Settings'!$D$7) -> 0
B16: =IF('⚙️ Settings'!C24="","",'⚙️ Settings'!B24&" "&'⚙️ Settings'!C24) -> 🙏 Spiritual | C16: =IF($B16="","",'⚙️ Settings'!D24) -> 0 | D16: =IF($B16="","",'📅 Daily Tracker'!K16) -> 0 | E16: =IF($B16="","",D16-C16) -> 0 | F16: =IF(OR($B16="",C16=0),"",D16/C16) | G16: =IF($B16="","",C16/'⚙️ Settings'!$D$7) -> 0
B17: =IF('⚙️ Settings'!C25="","",'⚙️ Settings'!B25&" "&'⚙️ Settings'!C25) -> 🚗 Travel | C17: =IF($B17="","",'⚙️ Settings'!D25) -> 0 | D17: =IF($B17="","",'📅 Daily Tracker'!K17) -> 0 | E17: =IF($B17="","",D17-C17) -> 0 | F17: =IF(OR($B17="",C17=0),"",D17/C17) | G17: =IF($B17="","",C17/'⚙️ Settings'!$D$7) -> 0
... B23: =IF('⚙️ Settings'!C31="","",'⚙️ Settings'!B31&" "&'⚙️ Settings'!C31) | C23: =IF($B23="","",'⚙️ Settings'!D31) | D23: =IF($B23="","",'📅 Daily Tracker'!K23) | E23: =IF($B23="","",D23-C23) | F23: =IF(OR($B23="",C23=0),"",D23/C23) | G23: =IF($B23="","",C23/'⚙️ Settings'!$D$7)
B25: Total allocated / logged | C25: =SUM(C6:C23) -> 166.08333 | D25: =SUM(D6:D23) -> 0
B26: Free / remaining hours | C26: ='⚙️ Settings'!$D$7-C25 -> 1.9166667 | D26: ='⚙️ Settings'!$D$7-D25 -> 168
B27: Utilization | C27: =C25/'⚙️ Settings'!$D$7 -> 0.98859127 | D27: =D25/'⚙️ Settings'!$D$7 -> 0

Sheet 🗓️ Monthly Tracker
B2: 🗓️ Monthly Tracker — the month, projected
B3: Weekly plan × 4 weeks (change the constant on ⚙️ Settings). Actuals extrapolate the current week.
B5: Category | C5: Weekly plan | D5: Monthly plan | E5: Monthly actual* | F5: Variance | G5: % of month
B6: =IF('⚙️ Settings'!C14="","",'⚙️ Settings'!B14&" "&'⚙️ Settings'!C14) -> 😴 Sleep | C6: =IF($B6="","",'⚙️ Settings'!D14) -> 57.166667 | D6: =IF($B6="","",C6*'⚙️ Settings'!$D$8) -> 228.66667 | E6: =IF($B6="","",'📈 Weekly Review'!D6*'⚙️ Settings'!$D$8) -> 0 | F6: =IF($B6="","",E6-D6) -> -228.66667 | G6: =IF($B6="","",D6/('⚙️ Settings'!$D$7*'⚙️ Settings'!$D$8)) -> 0.34027778
B7: =IF('⚙️ Settings'!C15="","",'⚙️ Settings'!B15&" "&'⚙️ Settings'!C15) -> 💻 Work | C7: =IF($B7="","",'⚙️ Settings'!D15) -> 53 | D7: =IF($B7="","",C7*'⚙️ Settings'!$D$8) -> 212 | E7: =IF($B7="","",'📈 Weekly Review'!D7*'⚙️ Settings'!$D$8) -> 0 | F7: =IF($B7="","",E7-D7) -> -212 | G7: =IF($B7="","",D7/('⚙️ Settings'!$D$7*'⚙️ Settings'!$D$8)) -> 0.31547619
B8: =IF('⚙️ Settings'!C16="","",'⚙️ Settings'!B16&" "&'⚙️ Settings'!C16) -> 🍕 Food | C8: =IF($B8="","",'⚙️ Settings'!D16) -> 5.9166667 | D8: =IF($B8="","",C8*'⚙️ Settings'!$D$8) -> 23.666667 | E8: =IF($B8="","",'📈 Weekly Review'!D8*'⚙️ Settings'!$D$8) -> 0 | F8: =IF($B8="","",E8-D8) -> -23.666667 | G8: =IF($B8="","",D8/('⚙️ Settings'!$D$7*'⚙️ Settings'!$D$8)) -> 0.035218254
B9: =IF('⚙️ Settings'!C17="","",'⚙️ Settings'!B17&" "&'⚙️ Settings'!C17) -> 🧹 Household Chores | C9: =IF($B9="","",'⚙️ Settings'!D17) -> 6 | D9: =IF($B9="","",C9*'⚙️ Settings'!$D$8) -> 24 | E9: =IF($B9="","",'📈 Weekly Review'!D9*'⚙️ Settings'!$D$8) -> 0 | F9: =IF($B9="","",E9-D9) -> -24 | G9: =IF($B9="","",D9/('⚙️ Settings'!$D$7*'⚙️ Settings'!$D$8)) -> 0.035714286
B10: =IF('⚙️ Settings'!C18="","",'⚙️ Settings'!B18&" "&'⚙️ Settings'!C18) -> 👶 Childcare | C10: =IF($B10="","",'⚙️ Settings'!D18) -> 16 | D10: =IF($B10="","",C10*'⚙️ Settings'!$D$8) -> 64 | E10: =IF($B10="","",'📈 Weekly Review'!D10*'⚙️ Settings'!$D$8) -> 0 | F10: =IF($B10="","",E10-D10) -> -64 | G10: =IF($B10="","",D10/('⚙️ Settings'!$D$7*'⚙️ Settings'!$D$8)) -> 0.095238095
B11: =IF('⚙️ Settings'!C19="","",'⚙️ Settings'!B19&" "&'⚙️ Settings'!C19) -> 🏋️ Fitness | C11: =IF($B11="","",'⚙️ Settings'!D19) -> 10 | D11: =IF($B11="","",C11*'⚙️ Settings'!$D$8) -> 40 | E11: =IF($B11="","",'📈 Weekly Review'!D11*'⚙️ Settings'!$D$8) -> 0 | F11: =IF($B11="","",E11-D11) -> -40 | G11: =IF($B11="","",D11/('⚙️ Settings'!$D$7*'⚙️ Settings'!$D$8)) -> 0.05952381
B12: =IF('⚙️ Settings'!C20="","",'⚙️ Settings'!B20&" "&'⚙️ Settings'!C20) -> 📺 Entertainment | C12: =IF($B12="","",'⚙️ Settings'!D20) -> 12 | D12: =IF($B12="","",C12*'⚙️ Settings'!$D$8) -> 48 | E12: =IF($B12="","",'📈 Weekly Review'!D12*'⚙️ Settings'!$D$8) -> 0 | F12: =IF($B12="","",E12-D12) -> -48 | G12: =IF($B12="","",D12/('⚙️ Settings'!$D$7*'⚙️ Settings'!$D$8)) -> 0.071428571
B13: =IF('⚙️ Settings'!C21="","",'⚙️ Settings'!B21&" "&'⚙️ Settings'!C21) -> 👨‍👩‍👧 Relationships | C13: =IF($B13="","",'⚙️ Settings'!D21) -> 6 | D13: =IF($B13="","",C13*'⚙️ Settings'!$D$8) -> 24 | E13: =IF($B13="","",'📈 Weekly Review'!D13*'⚙️ Settings'!$D$8) -> 0 | F13: =IF($B13="","",E13-D13) -> -24 | G13: =IF($B13="","",D13/('⚙️ Settings'!$D$7*'⚙️ Settings'!$D$8)) -> 0.035714286
B14: =IF('⚙️ Settings'!C22="","",'⚙️ Settings'!B22&" "&'⚙️ Settings'!C22) -> 📚 Learning | C14: =IF($B14="","",'⚙️ Settings'!D22) -> 0 | D14: =IF($B14="","",C14*'⚙️ Settings'!$D$8) -> 0 | E14: =IF($B14="","",'📈 Weekly Review'!D14*'⚙️ Settings'!$D$8) -> 0 | F14: =IF($B14="","",E14-D14) -> 0 | G14: =IF($B14="","",D14/('⚙️ Settings'!$D$7*'⚙️ Settings'!$D$8)) -> 0
B15: =IF('⚙️ Settings'!C23="","",'⚙️ Settings'!B23&" "&'⚙️ Settings'!C23) -> 🌱 Personal Development | C15: =IF($B15="","",'⚙️ Settings'!D23) -> 0 | D15: =IF($B15="","",C15*'⚙️ Settings'!$D$8) -> 0 | E15: =IF($B15="","",'📈 Weekly Review'!D15*'⚙️ Settings'!$D$8) -> 0 | F15: =IF($B15="","",E15-D15) -> 0 | G15: =IF($B15="","",D15/('⚙️ Settings'!$D$7*'⚙️ Settings'!$D$8)) -> 0
B16: =IF('⚙️ Settings'!C24="","",'⚙️ Settings'!B24&" "&'⚙️ Settings'!C24) -> 🙏 Spiritual | C16: =IF($B16="","",'⚙️ Settings'!D24) -> 0 | D16: =IF($B16="","",C16*'⚙️ Settings'!$D$8) -> 0 | E16: =IF($B16="","",'📈 Weekly Review'!D16*'⚙️ Settings'!$D$8) -> 0 | F16: =IF($B16="","",E16-D16) -> 0 | G16: =IF($B16="","",D16/('⚙️ Settings'!$D$7*'⚙️ Settings'!$D$8)) -> 0
B17: =IF('⚙️ Settings'!C25="","",'⚙️ Settings'!B25&" "&'⚙️ Settings'!C25) -> 🚗 Travel | C17: =IF($B17="","",'⚙️ Settings'!D25) -> 0 | D17: =IF($B17="","",C17*'⚙️ Settings'!$D$8) -> 0 | E17: =IF($B17="","",'📈 Weekly Review'!D17*'⚙️ Settings'!$D$8) -> 0 | F17: =IF($B17="","",E17-D17) -> 0 | G17: =IF($B17="","",D17/('⚙️ Settings'!$D$7*'⚙️ Settings'!$D$8)) -> 0
... B23: =IF('⚙️ Settings'!C31="","",'⚙️ Settings'!B31&" "&'⚙️ Settings'!C31) | C23: =IF($B23="","",'⚙️ Settings'!D31) | D23: =IF($B23="","",C23*'⚙️ Settings'!$D$8) | E23: =IF($B23="","",'📈 Weekly Review'!D23*'⚙️ Settings'!$D$8) | F23: =IF($B23="","",E23-D23) | G23: =IF($B23="","",D23/('⚙️ Settings'!$D$7*'⚙️ Settings'!$D$8))
B25: Total | D25: =SUM(D6:D23) -> 664.33333 | E25: =SUM(E6:E23) -> 0
B26: Free time per month | D26: ='⚙️ Settings'!$D$7*'⚙️ Settings'!$D$8-D25 -> 7.6666667
B27: * extrapolates the current Daily Tracker week across the month.

Sheet 🎯 Annual Tracker
B2: 🎯 Annual Tracker — a year of this plan
B3: Weekly plan × 52 weeks. This is where small weekly numbers become life-sized.
B5: Category | C5: Weekly h | D5: Annual hours | E5: Annual days | F5: Annual weeks | G5: % of year
B6: =IF('⚙️ Settings'!C14="","",'⚙️ Settings'!B14&" "&'⚙️ Settings'!C14) -> 😴 Sleep | C6: =IF($B6="","",'⚙️ Settings'!D14) -> 57.166667 | D6: =IF($B6="","",C6*'⚙️ Settings'!$D$9) -> 2972.6667 | E6: =IF($B6="","",D6/'⚙️ Settings'!$D$6) -> 123.86111 | F6: =IF($B6="","",D6/'⚙️ Settings'!$D$7) -> 17.694444 | G6: =IF($B6="","",C6/'⚙️ Settings'!$D$7) -> 0.34027778
B7: =IF('⚙️ Settings'!C15="","",'⚙️ Settings'!B15&" "&'⚙️ Settings'!C15) -> 💻 Work | C7: =IF($B7="","",'⚙️ Settings'!D15) -> 53 | D7: =IF($B7="","",C7*'⚙️ Settings'!$D$9) -> 2756 | E7: =IF($B7="","",D7/'⚙️ Settings'!$D$6) -> 114.83333 | F7: =IF($B7="","",D7/'⚙️ Settings'!$D$7) -> 16.404762 | G7: =IF($B7="","",C7/'⚙️ Settings'!$D$7) -> 0.31547619
B8: =IF('⚙️ Settings'!C16="","",'⚙️ Settings'!B16&" "&'⚙️ Settings'!C16) -> 🍕 Food | C8: =IF($B8="","",'⚙️ Settings'!D16) -> 5.9166667 | D8: =IF($B8="","",C8*'⚙️ Settings'!$D$9) -> 307.66667 | E8: =IF($B8="","",D8/'⚙️ Settings'!$D$6) -> 12.819444 | F8: =IF($B8="","",D8/'⚙️ Settings'!$D$7) -> 1.8313492 | G8: =IF($B8="","",C8/'⚙️ Settings'!$D$7) -> 0.035218254
B9: =IF('⚙️ Settings'!C17="","",'⚙️ Settings'!B17&" "&'⚙️ Settings'!C17) -> 🧹 Household Chores | C9: =IF($B9="","",'⚙️ Settings'!D17) -> 6 | D9: =IF($B9="","",C9*'⚙️ Settings'!$D$9) -> 312 | E9: =IF($B9="","",D9/'⚙️ Settings'!$D$6) -> 13 | F9: =IF($B9="","",D9/'⚙️ Settings'!$D$7) -> 1.8571429 | G9: =IF($B9="","",C9/'⚙️ Settings'!$D$7) -> 0.035714286
B10: =IF('⚙️ Settings'!C18="","",'⚙️ Settings'!B18&" "&'⚙️ Settings'!C18) -> 👶 Childcare | C10: =IF($B10="","",'⚙️ Settings'!D18) -> 16 | D10: =IF($B10="","",C10*'⚙️ Settings'!$D$9) -> 832 | E10: =IF($B10="","",D10/'⚙️ Settings'!$D$6) -> 34.666667 | F10: =IF($B10="","",D10/'⚙️ Settings'!$D$7) -> 4.952381 | G10: =IF($B10="","",C10/'⚙️ Settings'!$D$7) -> 0.095238095
B11: =IF('⚙️ Settings'!C19="","",'⚙️ Settings'!B19&" "&'⚙️ Settings'!C19) -> 🏋️ Fitness | C11: =IF($B11="","",'⚙️ Settings'!D19) -> 10 | D11: =IF($B11="","",C11*'⚙️ Settings'!$D$9) -> 520 | E11: =IF($B11="","",D11/'⚙️ Settings'!$D$6) -> 21.666667 | F11: =IF($B11="","",D11/'⚙️ Settings'!$D$7) -> 3.0952381 | G11: =IF($B11="","",C11/'⚙️ Settings'!$D$7) -> 0.05952381
B12: =IF('⚙️ Settings'!C20="","",'⚙️ Settings'!B20&" "&'⚙️ Settings'!C20) -> 📺 Entertainment | C12: =IF($B12="","",'⚙️ Settings'!D20) -> 12 | D12: =IF($B12="","",C12*'⚙️ Settings'!$D$9) -> 624 | E12: =IF($B12="","",D12/'⚙️ Settings'!$D$6) -> 26 | F12: =IF($B12="","",D12/'⚙️ Settings'!$D$7) -> 3.7142857 | G12: =IF($B12="","",C12/'⚙️ Settings'!$D$7) -> 0.071428571
B13: =IF('⚙️ Settings'!C21="","",'⚙️ Settings'!B21&" "&'⚙️ Settings'!C21) -> 👨‍👩‍👧 Relationships | C13: =IF($B13="","",'⚙️ Settings'!D21) -> 6 | D13: =IF($B13="","",C13*'⚙️ Settings'!$D$9) -> 312 | E13: =IF($B13="","",D13/'⚙️ Settings'!$D$6) -> 13 | F13: =IF($B13="","",D13/'⚙️ Settings'!$D$7) -> 1.8571429 | G13: =IF($B13="","",C13/'⚙️ Settings'!$D$7) -> 0.035714286
B14: =IF('⚙️ Settings'!C22="","",'⚙️ Settings'!B22&" "&'⚙️ Settings'!C22) -> 📚 Learning | C14: =IF($B14="","",'⚙️ Settings'!D22) -> 0 | D14: =IF($B14="","",C14*'⚙️ Settings'!$D$9) -> 0 | E14: =IF($B14="","",D14/'⚙️ Settings'!$D$6) -> 0 | F14: =IF($B14="","",D14/'⚙️ Settings'!$D$7) -> 0 | G14: =IF($B14="","",C14/'⚙️ Settings'!$D$7) -> 0
B15: =IF('⚙️ Settings'!C23="","",'⚙️ Settings'!B23&" "&'⚙️ Settings'!C23) -> 🌱 Personal Development | C15: =IF($B15="","",'⚙️ Settings'!D23) -> 0 | D15: =IF($B15="","",C15*'⚙️ Settings'!$D$9) -> 0 | E15: =IF($B15="","",D15/'⚙️ Settings'!$D$6) -> 0 | F15: =IF($B15="","",D15/'⚙️ Settings'!$D$7) -> 0 | G15: =IF($B15="","",C15/'⚙️ Settings'!$D$7) -> 0
B16: =IF('⚙️ Settings'!C24="","",'⚙️ Settings'!B24&" "&'⚙️ Settings'!C24) -> 🙏 Spiritual | C16: =IF($B16="","",'⚙️ Settings'!D24) -> 0 | D16: =IF($B16="","",C16*'⚙️ Settings'!$D$9) -> 0 | E16: =IF($B16="","",D16/'⚙️ Settings'!$D$6) -> 0 | F16: =IF($B16="","",D16/'⚙️ Settings'!$D$7) -> 0 | G16: =IF($B16="","",C16/'⚙️ Settings'!$D$7) -> 0
B17: =IF('⚙️ Settings'!C25="","",'⚙️ Settings'!B25&" "&'⚙️ Settings'!C25) -> 🚗 Travel | C17: =IF($B17="","",'⚙️ Settings'!D25) -> 0 | D17: =IF($B17="","",C17*'⚙️ Settings'!$D$9) -> 0 | E17: =IF($B17="","",D17/'⚙️ Settings'!$D$6) -> 0 | F17: =IF($B17="","",D17/'⚙️ Settings'!$D$7) -> 0 | G17: =IF($B17="","",C17/'⚙️ Settings'!$D$7) -> 0
... B23: =IF('⚙️ Settings'!C31="","",'⚙️ Settings'!B31&" "&'⚙️ Settings'!C31) | C23: =IF($B23="","",'⚙️ Settings'!D31) | D23: =IF($B23="","",C23*'⚙️ Settings'!$D$9) | E23: =IF($B23="","",D23/'⚙️ Settings'!$D$6) | F23: =IF($B23="","",D23/'⚙️ Settings'!$D$7) | G23: =IF($B23="","",C23/'⚙️ Settings'!$D$7)
B25: 💡 PERSPECTIVE
B26: ="At this pace you will sleep "&TEXT('⚙️ Settings'!D14*'⚙️ Settings'!$D$9/24,"0")&" full days this year." -> At this pace you will sleep 124 full days this year.
B27: ="You will work "&TEXT('⚙️ Settings'!D15*'⚙️ Settings'!$D$9,"#,##0")&" hours — that is "&TEXT('⚙️ Settings'!D15*'⚙️ Settings'!$D$9/24,"0")&" days." -> You will work 2,756 hours — that is 115 days.
B28: ="Free, unallocated time adds up to "&TEXT(MAX(0,'⚙️ Settings'!$D$34)*'⚙️ Settings'!$D$9,"#,##0")&" hours a year. Spend them on purpose." -> Free, unallocated time adds up to 100 hours a year. Spend them on purpose.

Sheet 📊 Dashboard
B2: 👉 Current Week: How do you spend your 168 hours of the week at the moment? | H2: 💬 WEEKLY | I2: 📆 MONTHLY | J2: 🎉 ANNUALLY
G3: ⌛ HOURS USED | H3: ='⚙️ Settings'!$D$33 -> 166.08333 | I3: ='⚙️ Settings'!$D$33*'⚙️ Settings'!$D$8 -> 664.33333 | J3: ='⚙️ Settings'!$D$33*'⚙️ Settings'!$D$9 -> 8636.3333
G4: ⌛ HOURS FREE | H4: ='⚙️ Settings'!$D$34 -> 1.9166667 | I4: ='⚙️ Settings'!$D$34*'⚙️ Settings'!$D$8 -> 7.6666667 | J4: ='⚙️ Settings'!$D$34*'⚙️ Settings'!$D$9 -> 99.666667
B5: ="Week "&WEEKNUM(TODAY(),21)&" · "&TEXT(TODAY(),"dddd, d mmmm yyyy") -> Week 31 · Sunday, 2 August 2026
L7: LIFE AREA | M7: HOURS
L8: =IF('⚙️ Settings'!C14="","",'⚙️ Settings'!B14&" "&'⚙️ Settings'!C14) -> 😴 Sleep | M8: ='⚙️ Settings'!D14 -> 57.166667
L9: =IF('⚙️ Settings'!C15="","",'⚙️ Settings'!B15&" "&'⚙️ Settings'!C15) -> 💻 Work | M9: ='⚙️ Settings'!D15 -> 53
L10: =IF('⚙️ Settings'!C16="","",'⚙️ Settings'!B16&" "&'⚙️ Settings'!C16) -> 🍕 Food | M10: ='⚙️ Settings'!D16 -> 5.9166667
L11: =IF('⚙️ Settings'!C17="","",'⚙️ Settings'!B17&" "&'⚙️ Settings'!C17) -> 🧹 Household Chores | M11: ='⚙️ Settings'!D17 -> 6
L12: =IF('⚙️ Settings'!C18="","",'⚙️ Settings'!B18&" "&'⚙️ Settings'!C18) -> 👶 Childcare | M12: ='⚙️ Settings'!D18 -> 16
L13: =IF('⚙️ Settings'!C19="","",'⚙️ Settings'!B19&" "&'⚙️ Settings'!C19) -> 🏋️ Fitness | M13: ='⚙️ Settings'!D19 -> 10
L14: =IF('⚙️ Settings'!C20="","",'⚙️ Settings'!B20&" "&'⚙️ Settings'!C20) -> 📺 Entertainment | M14: ='⚙️ Settings'!D20 -> 12
L15: =IF('⚙️ Settings'!C21="","",'⚙️ Settings'!B21&" "&'⚙️ Settings'!C21) -> 👨‍👩‍👧 Relationships | M15: ='⚙️ Settings'!D21 -> 6
L16: =IF('⚙️ Settings'!C22="","",'⚙️ Settings'!B22&" "&'⚙️ Settings'!C22) -> 📚 Learning | M16: ='⚙️ Settings'!D22 -> 0
L17: =IF('⚙️ Settings'!C23="","",'⚙️ Settings'!B23&" "&'⚙️ Settings'!C23) -> 🌱 Personal Development | M17: ='⚙️ Settings'!D23 -> 0
L18: =IF('⚙️ Settings'!C24="","",'⚙️ Settings'!B24&" "&'⚙️ Settings'!C24) -> 🙏 Spiritual | M18: ='⚙️ Settings'!D24 -> 0
L19: =IF('⚙️ Settings'!C25="","",'⚙️ Settings'!B25&" "&'⚙️ Settings'!C25) -> 🚗 Travel | M19: ='⚙️ Settings'!D25 -> 0
L20: =IF('⚙️ Settings'!C26="","",'⚙️ Settings'!B26&" "&'⚙️ Settings'!C26) -> 🗂️ Admin | M20: ='⚙️ Settings'!D26 -> 0
L21: ✅ Free Time | M21: =MAX(0,'⚙️ Settings'!$D$34) -> 1.9166667
L22: =IF('⚙️ Settings'!C27="","",'⚙️ Settings'!B27&" "&'⚙️ Settings'!C27) | M22: =IF('⚙️ Settings'!C27="","",'⚙️ Settings'!D27)
L23: =IF('⚙️ Settings'!C28="","",'⚙️ Settings'!B28&" "&'⚙️ Settings'!C28) | M23: =IF('⚙️ Settings'!C28="","",'⚙️ Settings'!D28)
L24: =IF('⚙️ Settings'!C29="","",'⚙️ Settings'!B29&" "&'⚙️ Settings'!C29) | M24: =IF('⚙️ Settings'!C29="","",'⚙️ Settings'!D29)
L25: =IF('⚙️ Settings'!C30="","",'⚙️ Settings'!B30&" "&'⚙️ Settings'!C30) | M25: =IF('⚙️ Settings'!C30="","",'⚙️ Settings'!D30)
B26: 🚦 SIGNALS | G26: 🔭 HORIZONS | L26: =IF('⚙️ Settings'!C31="","",'⚙️ Settings'!B31&" "&'⚙️ Settings'!C31) | M26: =IF('⚙️ Settings'!C31="","",'⚙️ Settings'!D31)
B27: =IF('⚙️ Settings'!D15>60,"🔴 Work is over 60 h/week — burnout territory. Cut or delegate.",IF('⚙️ Settings'!D15>55,"🟡 Work is above 55 h/week — watch the load.","🟢 Work load is sustainable.")) -> 🟢 Work load is sustainable. | H27: Weekly | I27: Monthly | J27: Yearly | L27: ❌ Total Non-Free Time | M27: ='⚙️ Settings'!$D$33 -> 166.08333
B28: =IF('⚙️ Settings'!D14<49,"🔴 Sleep is under 7 h/night — recovery is your first lever.","🟢 Sleep is on target.") -> 🟢 Sleep is on target. | G28: Hours used | H28: ='⚙️ Settings'!$D$33/7 -> 23.72619 | I28: ='⚙️ Settings'!$D$33 -> 166.08333 | J28: ='⚙️ Settings'!$D$33*'⚙️ Settings'!$D$8 -> 664.33333 | K28: ='⚙️ Settings'!$D$33*'⚙️ Settings'!$D$9 -> 8636.3333
B29: =IF('⚙️ Settings'!D19<3,"🟡 Fitness is under 3 h/week — schedule workouts first, not last.","🟢 Fitness habit is funded.") -> 🟢 Fitness habit is funded. | G29: Free time | H29: =MAX(0,'⚙️ Settings'!$D$34)/7 -> 0.27380952 | I29: =MAX(0,'⚙️ Settings'!$D$34) -> 1.9166667 | J29: =MAX(0,'⚙️ Settings'!$D$34)*'⚙️ Settings'!$D$8 -> 7.6666667 | K29: =MAX(0,'⚙️ Settings'!$D$34)*'⚙️ Settings'!$D$9 -> 99.666667
B30: =IF('⚙️ Settings'!$D$34<0,"🔴 You have allocated MORE than 168 hours — something must give.",IF('⚙️ Settings'!$D$34<5,"🟡 Under 5 h of true free time — build in slack.","🟢 Healthy buffer of free time.")) -> 🟡 Under 5 h of true free time — build in slack. | G30: Productive | H30: ='⚙️ Settings'!$D$35/7 -> 9 | I30: ='⚙️ Settings'!$D$35 -> 63 | J30: ='⚙️ Settings'!$D$35*'⚙️ Settings'!$D$8 -> 252 | K30: ='⚙️ Settings'!$D$35*'⚙️ Settings'!$D$9 -> 3276
B31: =IF('⚙️ Settings'!D21<3,"🟡 Relationships get under 3 h/week — book the quality time.","🟢 Relationships are funded.") -> 🟢 Relationships are funded. | G31: Sleep | H31: ='⚙️ Settings'!D14/7 -> 8.1666667 | I31: ='⚙️ Settings'!D14 -> 57.166667 | J31: ='⚙️ Settings'!D14*'⚙️ Settings'!$D$8 -> 228.66667 | K31: ='⚙️ Settings'!D14*'⚙️ Settings'!$D$9 -> 2972.6667
B34: 🎯 BALANCE SCORE | D34: ⚡ UTILIZATION | F34: 💼 PRODUCTIVE
B35: =ROUND(100*(('⚙️ Settings'!D14>=49)*('⚙️ Settings'!D14<=63)+('⚙️ Settings'!D15<=55)*1+('⚙️ Settings'!D19>=3)*1+('⚙️ Settings'!D21>=3)*1+(('⚙️ Settings'!D22+'⚙️ Settings'!D23)>=2)*1+('⚙️ Settings'!$D$34>=5)*1+('⚙️ Settings'!$D$34>=0)*1)/7,0) -> 71 | D35: ='⚙️ Settings'!$D$33/'⚙️ Settings'!$D$7 -> 0.98859127 | F35: ='⚙️ Settings'!$D$35 -> 63
B36: out of 100 | D36: of your 168 hours | F36: productive h / week

Sheet 📖 Start Here
B2: 📖 Start Here — how to run your 168 hours
B4: 🧭 THE IDEA
C5: Everyone gets exactly 24 hours a day and 168 hours a week. This workbook treats those 168 hours like a budget: you allocate them on 📝 Weekly Tracker, log reality on 📅 Daily Tracker, and everything reconciles automatically.
B7: ✏️ RULE #1 — ONLY EDIT LIGHT-BLUE CELLS
C8: Every editable cell has a light-blue background. Everything else is a formula — you never need to touch it.
B10: 🚀 GETTING STARTED (10 MINUTES)
C11: 1. Go to 📝 Weekly Tracker and answer the guided sentences (blue cells). The sheet already contains realistic example values — replace them with yours.
C12: 2. Watch 📊 Dashboard — HOURS USED / HOURS FREE, the charts and the Signals update live.
C13: 3. During the week, log real hours on 📅 Daily Tracker.
C14: 4. Review 📈 Weekly Review at week end: planned vs actual, and where the gap is.
B16: ➕ ADDING A CUSTOM CATEGORY
C17: Open ⚙️ Settings, find the light-blue rows at the bottom of the Master Category Table, and type an emoji, a name and weekly hours. It appears in every tracker and the Dashboard automatically.
B19: 🎯 BALANCE SCORE
C20: A 0–100 gauge of how humane the week is: sleep 49–63 h, work ≤ 55 h, fitness ≥ 3 h, relationships ≥ 3 h, learning + personal development ≥ 2 h, free time ≥ 5 h, nothing over-allocated. 80+ = sustainable.
B22: 🔁 A NEW WEEK
C23: Select the light-blue grid on 📅 Daily Tracker and press Delete. Your plan stays.
B25: 📐 ASSUMPTIONS
C26: Monthly = weekly × 4, yearly = weekly × 52 (the reference sheet's convention). Both constants are editable on ⚙️ Settings — use 4.345 / 52.18 for calendar-accurate maths. Default input values reproduce the reference screenshots (166.1 h used, 1.9 h free).
